# 8장(예외 처리)

- 코루틴의 비동기 작업을 수행하는 코루틴의 예외 처리 역시 중요!
    
    → IO 작업이 많아 예측할 수 없는 예외 발생 시 앱의 안정성이 떨어지기 때문
    

## 코루틴의 예외 전파

### 코루틴에서 예외가 전파되는 방식

- 코루틴 실행 중 예외 발생 시 해당 코루틴은 취소되고, 부모 코루틴으로 전파됨
- 이때 부모 코루틴에서도 예외를 제대로 해결하지 못한다면 루트 코루틴까지 예외가 전파될 수 있다.

<img width="790" height="525" alt="image" src="https://github.com/user-attachments/assets/858864ac-365e-492f-aed6-db61057f0d33" />

<img width="790" height="525" alt="image" src="https://github.com/user-attachments/assets/939e09a1-d1db-497b-b06a-ff718460d632" />

<img width="790" height="525" alt="image" src="https://github.com/user-attachments/assets/2f0477f2-919a-44b2-9b3b-5710b2cd676a" />


→ **코루틴의 예외 전파를 제대로 막지 못하면 루트 코루틴이 취소되고 구조화된 코루틴 모두 취소될 수 있다.**

### 예제로 알아보는 예외 전파

```kotlin
fun main() = runBlocking<Unit> {
    launch(CoroutineName("Coroutine1")) {
        launch(CoroutineName("Coroutine3")) {
            throw Exception("예외 발생")
        }
        delay(100L)
        println("${Thread.currentThread().name} 코루틴 실행")
        launch(CoroutineName("Coroutine2")) {
            delay(100L)
            println("${Thread.currentThread().name} 코루틴 실행")
        }
        delay(1000L)
    }
}

/*
Exception in thread "main" java.lang.Exception: 예외 발생
	at study.FKt$main$1$1$1.invokeSuspend(f.kt:11)
	at kotlin.coroutines.jvm.internal.BaseContinuationImpl.resumeWith(ContinuationImpl.kt:33)
	at kotlinx.coroutines.DispatchedTask.run(DispatchedTask.kt:104)
	at kotlinx.coroutines.EventLoopImplBase.processNextEvent(EventLoop.common.kt:277)
	at kotlinx.coroutines.BlockingCoroutine.joinBlocking(Builders.kt:95)
	at kotlinx.coroutines.BuildersKt__BuildersKt.runBlocking(Builders.kt:69)
	at kotlinx.coroutines.BuildersKt.runBlocking(Unknown Source)
	at kotlinx.coroutines.BuildersKt__BuildersKt.runBlocking$default(Builders.kt:48)
	at kotlinx.coroutines.BuildersKt.runBlocking$default(Unknown Source)
	at study.FKt.main(f.kt:8)
	at study.FKt.main(f.kt)
*/
```

## 예외 전파 제한

### Job 객체를 사용한 예외 전파 제한

1. Job 객체를 사용해 예외 전파 제한하기
    - **코루틴 예외 전파를 위해서 코루틴의 구조화를 깨면 된다!**
        - 자신의 부모 코루틴으로만 예외 전파하기에 코루틴의 구조화를 깨면 예외가 전파되지 않는다.
        - **새로운 Job 객체를 만들어 구조화 깨고 싶은 코루틴에 연결하면 된다.**
    
    ```kotlin
    fun main() = runBlocking<Unit> {
        launch(CoroutineName("Parent Coroutine")) {
            launch(CoroutineName("Coroutine1") + Job()) {
                launch(CoroutineName("Coroutine3")) {
                    throw Exception("예외 발생")
                }
                delay(100L)
                println("${Thread.currentThread().name} 코루틴 실행")
            }
            launch(CoroutineName("Coroutine2")) {
                delay(100L)
                println("${Thread.currentThread().name} 코루틴 실행")
            }
        }
        delay(1000L)
    }
    
    /*
    Exception in thread "main @Coroutine1#3" java.lang.Exception: 예외 발생
    	at study.FKt$main$1$1$1$1.invokeSuspend(f.kt:13)
    	at kotlin.coroutines.jvm.internal.BaseContinuationImpl.resumeWith(ContinuationImpl.kt:33)
    	at kotlinx.coroutines.DispatchedTask.run(DispatchedTask.kt:104)
    	at kotlinx.coroutines.EventLoopImplBase.processNextEvent(EventLoop.common.kt:277)
    	at kotlinx.coroutines.BlockingCoroutine.joinBlocking(Builders.kt:95)
    	at kotlinx.coroutines.BuildersKt__BuildersKt.runBlocking(Builders.kt:69)
    	at kotlinx.coroutines.BuildersKt.runBlocking(Unknown Source)
    	at kotlinx.coroutines.BuildersKt__BuildersKt.runBlocking$default(Builders.kt:48)
    	at kotlinx.coroutines.BuildersKt.runBlocking$default(Unknown Source)
    	at study.FKt.main(f.kt:9)
    	at study.FKt.main(f.kt)
    	Suppressed: kotlinx.coroutines.internal.DiagnosticCoroutineContextException: [CoroutineName(Coroutine1), CoroutineId(3), "Coroutine1#3":StandaloneCoroutine{Cancelling}@544fe44c, BlockingEventLoop@31610302]
    main @Coroutine2#4 코루틴 실행
    */
    ```
    
    → **`Coroutine1` 에서 코루틴의 구조화를 끊었기 때문에 1까지는 예외가 전파되지만, 부모 코루틴으로는 예외가 전파되지 않음!**
    
    - Job 객체를 사용한 예외 전파 제한의 한계
        - Job 객체를 사용해서 작은 작업의 구조화를 깨면 큰 작업에 취소가 요청되어도 작은 작업은 취소되지 않으면 비동기 작업을 불안정하게 만든다.
        
        ```kotlin
        fun main() = runBlocking<Unit> {
            val parentJob = launch(CoroutineName("Parent Coroutine")) {
                launch(CoroutineName("Coroutine1") + Job()) {
                    launch(CoroutineName("Coroutine3")) {
                        delay(100L)
                        println("${Thread.currentThread().name} 코루틴 실행")
                    }
                }
                launch(CoroutineName("Coroutine2")) {
                    delay(100L)
                    println("${Thread.currentThread().name} 코루틴 실행")
                }
            }
            delay(20L)
            parentJob.cancel()
            delay(1000L)
        }
        
        // main @Coroutine3#5 코루틴 실행
        ```
        
        - parentJob 의 코루틴을 취소했지만, Coroutine1 부터는 구조화가 깨져 해당 Coroutine3는 실행된 것을 확인할 수 있다.
        
        → 그렇다면 구조화를 깨지 않으면서 예외 전파를 제한할 수 있는 방법은 무엇일까?
        
2. SupervisorJob 객체를 사용한 예외 전파 제한
- SupervisorJob 객체를 사용해 예외 전파 제한하기
    - `Supervisor Job` : 자식 코루틴으로부터 예외를 전파받지 않는 특수한 Job 객체
        
        → **하나의 자식 코루틴에서 발생한 예외가 다른 자식 코루틴에게 영향을 미치지 못하도록 만드는 데 사용**된다.
        
    
    ```kotlin
    public fun SupervisorJob(parent: Job? = null) : CompletableJob =
    	SupervisorJobImpl(parent)
    ```
    
    - 매개변수에 부모 Job 객체 넘기면 부모 Job이 있는 SupervisorJob
    - 매개변수 없이 사용 시 루트 Job인 SupervisorJob
- 코루틴의 구조화를 깨지 않고 SupervisorJob 사용하기
    - 매개변수에 부모 Job 객체 넘겨 구조화 깨트리지 않을 수 있다.
    - `SupervisorJob()` 을 통해 생성된 Job 객체는 Job()을 통해 생성된 Job 객첻와 같이 자동으로 완료 처리 되지 않는다.
- SupervisorJob을 CoroutineScope와 함께 사용하기
    - `CoroutineScope` 의 `CoroutineContext` 에 SupervisorJob 객체가 설정되면, 자식 코루틴에서 발생하는 예외가 다른 자식 코루틴으로 전파되지 않음
- SupervisorJob을 사용할 때 흔히 하는 실수
    - 예외 전파 방지를 위해 코루틴 빌더 함수의 context 인자에 `SupervisorJob()` 객체를 넘기는 것!
    
    ```kotlin
    fun main() = runBlocking<Unit> {
        launch(CoroutineName("Parent 코루틴") + SupervisorJob()) {
            launch(CoroutineName("코루틴 1")) {
                launch(CoroutineName("코루틴 3")) {
                    throw Exception("예외")
                }
                delay(100L)
                println("${Thread.currentThread().name} 코루틴 실행")
            }
            launch(CoroutineName("코루틴 2")) {
                delay(100L)
                println("${Thread.currentThread().name} 코루틴 실행")
            }
        }
        delay(100L)
    }
    
    /*
    Exception in thread "main @코루틴 2#4" java.lang.Exception: 예외
    	at study.FKt$main$1$1$1$1.invokeSuspend(f.kt:13)
    */
    ```
    
    - **launch 함수에 context 인자를 Job 객체로 넣으면 해당 Job 객체를 부모로 새로운 객체 생성됨**
    
    → `SupervisorJob()` 객체가 루트 코루틴이 되기에 다른 자식 코루틴으로 취소 전파됨
    

### supervisorScope 를 사용한 예외 전파 제한

- `supervisorScope` 함수 사용해 예외 전파를 제한한다.
- `supervisorScope 함수` : SupervisorScope 객체 가진 CoroutineScope 객체 생성 + 해당 객체는 함수 호출한 코루틴의 Job 객체의 부모 객체가 된다.
    
    **→ 쉽게 구조화를 깨지 않고 예외 전파 제한할 수 있다.**
    
    **→ 코루틴 모두 실행 완료 시 자동으로 완료 처리**
    

## CoroutineExceptionHandler를 사용한 예외 처리

### CoroutineExceptionHandler 생성

```kotlin
public inline fun CoroutineExceptionHandler(crossinline handler: 
(CoroutineContext, Throwable) -> Unit): CoroutineExceptionHandle
```

- handler 는 CoroutineContext와 Throwable 타입의 매개변수 갖는 람다식 → 예외 발생 시 어떤 동작 수행할 지 입력해 예외 처리
    
    ```kotlin
    val exceptionHandler = CoroutineExceptionHandler { coroutineContext,
    throwable ->
    	println("[예외 발생] ${throwable}")
    }
    ```
    

### CoroutineExceptionHandler 사용

- `CoroutineExceptionHandler` 를 CoroutineScope 인자로 넣으면 해당 예외 환경을 상속 받는다.

### 처리되지 않은 예외만 처리하는 CoroutineExceptionHandler

- 해당 객체는 처리되지 않은 예외만 처리한다.
    - **즉, 자식 코루틴 → 부모 코루틴 예외 전파 시 본인은 예외 처리가 된 것으로 보아 ExceptionHandler 수행 X**
- 구조화된 코루틴 상에 여러 CoroutineExceptionHandler 객체 설정되어 있어도, 예외 마지막으로 처리하는 위치에 설정된 CoroutineExceptionHandler 객체만 예외 처리한다.
    
    → 해당 객체는 ‘공통 예외 처리기’ 로 동작한다.
    

### CoroutineEcxeptionHandler 의 예외 처리 위치

- 루트 코루틴에 설정된 exceptionHandler 가 예외를 처리한다.

### CoroutineExceptionHandler 를 사용해야 하는 경우

- handlerException 함수가 호출될 때는 이미 해당 예외로 인해 코루틴이 완료된 상태 이기에 예외 복구 X
- 사용하는 경우
    - 예외 로깅
    - 오류 메시지 표시

### CoroutineExceptionHandler는 예외 전파를 제한하지 않는다

- try - catch 문처럼 동작해 예외 전파를 제한한다고 생각하지만, 실제론 마지막으로 처리되는 위치에서 예외 처리할 뿐 예외 전파 제한하지 않는다.

## try catch 문을 사용한 예외 처리

### try catch 문을 사용해 코루틴 예외 처리하기

- try-catch 문을 통해 예외를 처리하면 부모 코루틴인 runBlocking 코루틴으로 예외 전파 X
- 그러면 루트 코루틴으로 예외 전파되지 않아 다른 자식 코루틴도 정상 작동한다.

### 코루틴 빌더 함수에 대한 try catch 문은 코루틴의 예외를 잡지 못한다

- try-catch 를 코루틴 빌더 함수에 사용하면, 코루틴에서 발생한 예외를 잡지 못한다.
    - 빌더 함수는 코루틴 생성 시에만 사용되고, CoroutineDispatcher 에 의해 스레드에 분배되는 시점에 실행되기 때문이다.

## async의 예외 처리

### async의 예외 노출

- async 는 결괏값을 Deferred 객체로 감싸고 await 시점에 결괏값 노출한다.
    
    **→ 이 때 코루틴 실행 중 예외 발생해 결괏값 없다면 await 호출 시 예외 노출**
    

### async의 예외 전파

- async 또한 예외 발생 시 부모 코루틴으로 예외 전파한다.
    - await 호출하지 않아도 예외 발생된다.

## 전파되지 않는 예외

### 전파되지 않는 CancellationException

- `CancellationException` 예외 발생해도 부모 코루틴으로 전파되지 않음.

### 코루틴 취소 시 사용되는 JobCancellationException

- 그렇다면 왜 부모 코루틴으로 전파되지 않는가?
    - Job 객체에 대해 cancel 함수 호출하면 `CancellationException` 의 서브 클래스인 `JobCancellationException` 을 발생시켜 코루틴을 취소한다.

### withTimeOut 사용해 코루틴의 실행 시간 제한하기

```kotlin
public suspend fun <T> withTimeout(timeMillis: Long, block: suspend
CoroutineScope.() -> T): T 
```

- 매개변수로 실행 제한 시간을 밀리초 단위로 표현하는 timeMillis와 해당 시간 내에 실행돼야 할 작업인 block 가짐
    - withTimeOut 함수는 작업이 주어진 시간 내에 완료되지 않으면 `TimeOutCancellationException 발생`
