# 8장 - 예외 처리

- 애플리케이션은 여러 예외 상황에 노출된다. 안정적인 애플리케이션을 위해서는 예외를 적절하게 처리하는 것이 중요하다.
- 같은 맥락에서 애플리케이션의 비동기 작업을 수행하는 코루틴의 예외 처리 또한 중요하다. 특히, 코루틴의 비동기 작업은 네트워크 요청이나 데이터베이스 작업 같은 I/O 작업을 수행하는 데 쓰이는 경우가 많아 예측할
  수 없는 예외가 발생할 가능성이 높으므로 코루틴에 대한 적절한 예외 처리는 안정적인 애플리케이션을 만드는 데 필수적이다.

## 8.1. 코루틴의 예외 전파

### 8.1.1. 코루틴에서 예외가 전파되는 방식

- 코루틴 실행 도중 예외가 발생하면 예외가 발생한 코루틴은 취소되고 부모 코루틴으로 예외가 전파된다. 만약, 부모 코루틴에서도 예외가 적절히 처리되지 않으면 부모 코루틴도 취소되고 예외는 다시 상위 코루틴으로
  전파되는데 이것이 반복되면 최상위 코루틴인 루트 코루틴까지 예외가 전파될 수 있다.
- 코루틴이 예외를 전파받아 취소되면 해당 코루틴만 취소되는 것이 아니라 코루틴의 특성에 따라 해당 코루틴의 하위에 있는 모든 코루틴에게 취소가 전파된다. 즉, 코루틴의 예외 전파를 제대로 막지 못해 루트 코루틴이
  취소되면 구조화된 코루틴이 모두 취소될 수 있다.

<img width="400" alt="image" src="https://github.com/user-attachments/assets/276e4676-6b97-480f-9ca6-8a04c1de0398" />

### 8.1.2. 예제로 알아보는 예외 전파

```kotlin
fun main(): Unit =
    runBlocking {
        launch(CoroutineName("Coroutine1")) {
            launch(CoroutineName("Coroutine3")) {
                throw Exception("예외 발생")
            }
            delay(100L)
            println("[${Thread.currentThread().name}] 코루틴 실행")
        }
        launch(CoroutineName("Coroutine2")) {
            delay(100L)
            println("[${Thread.currentThread().name}] 코루틴 실행")
        }
        delay(1000L)
    }
```

<img width="600" alt="image" src="https://github.com/user-attachments/assets/fc90a1eb-22db-4251-9f06-52f18eab2558" />

- Coroutine3 코루틴에서 발생하는 예외는 처리되는 부분이 없기 때문에 위와 같이 Coroutine1 코루틴을 거쳐 runBlocking 함수를 통해 만들어지는 루트 코루틴까지 전파된다. 따라서, 루트
  코루틴이 취소되므로 그에 따라 하위에 있는 Coroutine2 코루틴에도 취소가 전파된다.
- 코드를 실행하면 예외가 발생했다는 로그만 나온다. Coroutine3 코루틴에서 발생한 예외가 모든 코루틴을 취소시킨 것이다.
- 코루틴의 구조화는 큰 작업을 연관된 작은 작업으로 나누는 방식으로 이뤄진다는 점을 기억하자. 만약 작은 작업에서 발생한 예외로 인해 큰 작업이 취소되면 애플리케이션의 안정성에 문제가 생길 수 있다. 이런 문제를
  해결하기 위해 코루틴은 예외 전파를 제한하는 여러 장치를 가진다.

## 8.2. 예외 전파 제한

### 8.2.1. Job 객체를 사용한 예외 전파 제한

8.2.1.1. Job 객체를 사용해 예외 전파 제한하기

- 코루틴의 예외 전파를 제한하기 위한 첫 번째 방법은 코루틴의 구조화를 깨는 것이다. 코루틴은 자신의 부모 코루틴으로만 예외를 전파하는 특성을 가지므로 부모 코루틴과의 구조화를 깬다면 예외가 전파되지 않는다. 부모
  코루틴과의 구조화를 깨는 방법은 새로운 Job 객체를 만들어 구조화를 깨고 싶은 코루틴을 연결하면 된다.

    ```kotlin
    fun main(): Unit =
        runBlocking {
            launch(CoroutineName("Parent Coroutine")) {
                launch(CoroutineName("Coroutine1") + Job()) {
                    // 새로운 Job 객체를 만들어 Coroutine1에 연결
                    launch(CoroutineName("Coroutine3")) {
                        throw Exception("예외 발생")
                    }
                    delay(100L)
                    println("[${Thread.currentThread().name}] 코루틴 실행")
                }
                launch(CoroutineName("Coroutine2")) {
                    delay(100L)
                    println("[${Thread.currentThread().name}] 코루틴 실행")
                }
            }
            delay(1000L)
        }
    ```

    - Coroutine1 코루틴은 Job()을 사용해 새로운 Job 객체를 부모 Job으로 설정함으로써 Parent Coroutine 코루틴과의 구조화를 깬다. 따라서 Coroutine3 코루틴이 예외를
      발생시켜 부모 코루틴인 Coroutine1 코루틴으로 예외를 전파하더라도 Parent Coroutine 코루틴으로 예외가 전파되지 않는다. 대신 새로 만들어진 Job 객체에 예외를 전파한다.

<img width="600" alt="image" src="https://github.com/user-attachments/assets/d9f40035-f81d-4e59-b839-7aca3e57bde1" />
<br>
<img width="600" alt="image" src="https://github.com/user-attachments/assets/87753ef3-c1df-43b1-802c-800b08480a20" />

- 실행 결과를 보면 예외가 발생했음에도 Corotuine2는 정상 실행되는 것을 볼 수 있다.

8.2.1.2 Job 객체를 사용한 예외 전파 제한의 한계

- Job 객체를 생성해 코루틴의 구조화를 깨는 것은 예외 전파를 제한하는 것뿐만 아니라 취소 전파도 제한시킨다. 만약, 작은 작업의 구조화가 깨진다면 큰 작업에 취소가 요청되더라도 작은 작업은 취소되지 않으며 이는
  비동기 작업을 불안정하게 만든다.

    ```kotlin
    fun main(): Unit =
        runBlocking {
            val parentJob =
                launch(CoroutineName("Parent Coroutine")) {
                    launch(CoroutineName("Coroutine1") + Job()) {
                        // 새로운 Job 객체를 만들어 Coroutine1에 연결
                        launch(CoroutineName("Coroutine3")) {
                            delay(100L)
                            println("[${Thread.currentThread().name}] 코루틴 실행")
                        }
                        delay(100L)
                        println("[${Thread.currentThread().name}] 코루틴 실행")
                    }
                    launch(CoroutineName("Coroutine2")) {
                        delay(100L)
                        println("[${Thread.currentThread().name}] 코루틴 실행")
                    }
                }
            delay(20L)
            parentJob.cancel() // Parent Coroutine에 취소 요청
            delay(1000L)
        }
    ```

    - Coroutine1 코루틴은 더 이상 Parent Coroutine 코루틴의 자식이 아니기 때문에 취소 전파가 제한된다. 하지만, 코루틴의 구조화는 일반적으로 큰 작업을 연관된 작은 작업으로 나누는
      방식으로 일어나기 때문에 안정적으로 동작하기 위해서는 Parent Coroutine이 취소되면 Coroutine1, Coroutine3 코루틴도 함께 취소되어야 한다.

<img width="600" alt="image" src="https://github.com/user-attachments/assets/d7efc8bf-e9de-4aa0-a14f-5fa53941e6aa" />

### 8.2.2. SupervisorJob 객체를 사용한 예외 전파 제한

8.2.2.1. SupervisorJob 객체를 사용해 예외 전파 제한하기

- 코루틴의 예외 전파를 제한하기 위한 2번째 방법은 SupervisorJob 객체를 사용하는 것이다. SupervisorJob 객체는 자식 코루틴으로부터 예외를 전파받지 않는 특수한 Job 객체로 하나의 자식
  코루틴에서 발생한 예외가 다른 자식 코루틴에게 영향을 미치지 못하도록 만드는 데 사용된다. 일반적인 객체는 자식 코루틴에서 예외가 발생하면 예외를 전파받아 취소되지만 SupervisorJob 객체는 예외를
  전파받지 않아 취소되지 않는다.

    ```kotlin
        public fun SupervisorJob(parent: Job? = null): CompletableJob = SupervisorJobImpl(parent)
        
        private class SupervisorJobImpl(parent: Job?) : JobImpl(parent) {
            override fun childCancelled(cause: Throwable): Boolean = false
        }
    ```

- SupervisorJob 생성 함수를 parent 인자 없이 사용하면 SupervisorJob 객체를 루트 Job으로 만들 수 있으며, parent 인자로 Job 객체를 넘기면 부모 Job이 있는
  SupervisorJob 객체를 만들 수 있다.

    ```kotlin
    fun main() =
        runBlocking {
            val supervisorJob = SupervisorJob()
            launch(CoroutineName("Coroutine1") + supervisorJob) {
                launch(CoroutineName("Coroutine3")) {
                    throw Exception("예외 발생")
                }
                delay(100L)
                println("[${Thread.currentThread().name}] 코루틴 실행")
            }
            launch(CoroutineName("Coroutine2") + supervisorJob) {
                delay(100L)
                println("[${Thread.currentThread().name}] 코루틴 실행")
            }
            delay(1000L)
        }
    ```

<img width="600" alt="image" src="https://github.com/user-attachments/assets/fe8aeb69-2aaf-4205-9be8-6b3250e15aa2" />

- 위 코드에서 supervisorJob 변수는 SupervisorJob()이 호출돼 만들어진 SupervisorJob 객체를 가리키며, Coroutine1과 Coroutine2는 부모 Job으로
  supervisorJob을 가진다. 따라서, Coroutine3 코루틴에서 발생한 예외는 Coroutine1로 전파되어 Coroutine1을 취소시키지만 Coroutine1은 supervisorJob으로 예외를
  전파하지 않는다.

 <img width="600" alt="image" src="https://github.com/user-attachments/assets/889ed282-fbea-401d-bdb5-3599c5a60cec" />

- 하지만 여전히 위 코드는 문제가 하나 있다. SupervisorJob 객체가 runBlocking이 호출돼 만들어진 Job 객체와의 구조화를 깬다는 점이다.

8.2.2.2. 코루틴의 구조화를 깨지 않고 SupervisorJob 사용하기

- 코루틴의 구조화를 깨지 않고 SupervisorJob 사용하기 위해서는 SupervisorJob의 인자로 부모 Job 객체를 넘기면 된다.

    ```kotlin
    fun main(): Unit =
        runBlocking {
            // supervisorJob의 parent로 runBlocking으로 생성된 Job 객체 설정
            val supervisorJob = SupervisorJob(parent = this.coroutineContext[Job])
            launch(CoroutineName("Coroutine1") + supervisorJob) {
                launch(CoroutineName("Coroutine3")) {
                    throw Exception("예외 발생")
                }
                delay(100L)
                println("[${Thread.currentThread().name}] 코루틴 실행")
            }
            launch(CoroutineName("Coroutine2") + supervisorJob) {
                delay(100L)
                println("[${Thread.currentThread().name}] 코루틴 실행")
            }
            supervisorJob.complete() // supervisorJob 완료 처리
        }
    ```

<img width="600" alt="image" src="https://github.com/user-attachments/assets/7953dd73-6955-4a93-9208-3d129bb42c78" />

- SupervisorJob()을 통해 생성된 Job 객체는 Job()을 통해 생성된 Job 객체와 같이 자동으로 완료처리 되지 않는다.

<img width="600" alt="image" src="https://github.com/user-attachments/assets/1aa40a1f-9047-4e61-b41d-a53d62f419ac" />

- SupervisorJob 객체는 자식 코루틴으로부터 예외를 전파받아도 다른 자식 코루틴에게 예외를 전파하지 않으며, runBlocking 코루틴과의 구조화를 깨지도 않는다.

8.2.2.3. SupervisorJob을 CoroutineScope와 함께 사용하기

- 만약 CoroutineScope의 CoroutineContext에 SupervisorJob 객체가 설정된다면 CoroutineScope의 자식 코루틴에서 발생하는 예외가 다른 자식 코루틴으로 전파되지 않는다.
  CoroutineScope의 CoroutineContext에 SupervisorJob 객체를 설정하기 위해서는 CoroutineScope 생성 함수의 인자로 SupervisorJob()을 입력하면 된다.

    ```kotlin
    fun main(): Unit =
        runBlocking {
            val coroutineScope = CoroutineScope(SupervisorJob())
            coroutineScope.apply {
                launch(CoroutineName("Coroutine1")) {
                    launch(CoroutineName("Coroutine3")) {
                        throw Exception("예외 발생")
                    }
                    delay(100L)
                    println("[${Thread.currentThread().name}] 코루틴 실행")
                }
                launch(CoroutineName("Coroutine2")) {
                    delay(100L)
                    println("[${Thread.currentThread().name}] 코루틴 실행")
                }
            }
            delay(1000L)
        }
    ```

  <img width="800" alt="image" src="https://github.com/user-attachments/assets/a9a91692-52a9-4dd2-ba5d-228eb7d069f0" />

8.2.2.4. SupervisorJob을 사용할 때 흔히 하는 실수

- SupervisorJob을 사용 시 흔히 하는 실수는 예외 전파 방지를 위해 코루틴 빌더 함수의 context 인자에 SupervisorJob()을 넘기고, 코루틴 빌더 함수가 호출돼 생성되는 코루틴의 하위에
  자식 코루틴들을 생성하는 것이다.

    ```kotlin
    fun main() = runBlocking<Unit> {
    	  launch(CoroutineName("Parent Coroutine") + SupervisorJob()) {
    		    launch(CoroutineName("Coroutine1")) {
    			      launch(CoroutineName("Coroutine3")) {
    			        throw Exception("예외 발생")
    			      }
    			      delay(100L)
    			      println("[${Thread.currentThread().name}] 코루틴 실행")
    		    }
    		    launch(CoroutineName("Coroutine2")) {
    			      delay(100L)
    			      println("[${Thread.currentThread().name}] 코루틴 실행")
    		    }
    		  }
    	  delay(1000L)
    }
    ```

    - 8.2.2.3 코드와 같다 생각할 수 있지만, 실행하면 예외가 발생하고 아무것도 출력되지 않는다.
- 문제가 생기는 이유는 launch 함수는 context 인자에 Job 객체가 입력될 경우 해당 Job 객체를 부모로 하는 새로운 Job 객체를 만들기 때문이다. 즉, launch 함수에
  SupervisorJob()을 인자로 넘기면 SupervisorJob()을 통해 만들어지는 SupervisorJob 객체를 부모로 하는 새로운 Job 객체가 만들어진다.

  <img width="660" alt="image" src="https://github.com/user-attachments/assets/206511a2-e698-4191-976c-2fb2f9417373" />

- 따라서 Coroutine3에서 예외가 발생해 Coroutine1, Parent Coroutine까지 전파되고, Parent Coroutine이 취소되며 동시에 Coroutine2도 취소가 된다. Parent
  Coroutine의 예외가 SupervisorJob 객체로 전파되지는 않지만 이는 아무런 역할을 하지 못한다.
- SupervisorJob 객체는 강력한 예외 전파 방지 도구이지만 잘못 사용하면 그 기능을 제대로 수행하지 못할 수 있다. 따라서, SupervisorJob 객체가 Job 계층 구조의 어떤 위치에 있어야 하는지
  충분히 고민하고 사용해야 한다.

### 8.2.3. supervisorScope를 사용한 예외 전파 제한

- 코루틴의 예외 전파를 제한하기 위한 3번째 방법은 SupervisorJob() 대안으로 supervisorScope 함수를 사용하는 것이다. supervisorScope 함수는 SupervisorJob 객체를
  가진 CoroutineScope 객체를 생성하며, 이 객체는 supervisorScope 함수를 호출한 코루틴의 Job 객체를 부모로 가진다.
- 즉, supervisorScope를 사용하면 복잡한 설정 없이도 구조화를 깨지 않고 예외 전파를 제한할 수 있다. 또한 supervisorScope 내부에서 실행되는 코루틴은 SupervisorJob과 부모-자식
  관계로 구조화되는데 supervisorScope의 SupervisorJob 객체는 코드가 모두 실행되고 자식 코루틴도 모두 실행 완료되면 자동으로 완료 처리된다.

    ```kotlin
    fun main(): Unit =
        runBlocking {
            supervisorScope {
                launch(CoroutineName("Coroutine1")) {
                    launch(CoroutineName("Coroutine3")) {
                        throw Exception("예외 발생")
                    }
                    delay(100L)
                    println("[${Thread.currentThread().name}] 코루틴 실행")
                }
                launch(CoroutineName("Coroutine2")) {
                    delay(100L)
                    println("[${Thread.currentThread().name}] 코루틴 실행")
                }
            }
        }
    ```

- runBlocking 함수에 의해 Job 객체가 생성되고, Job 객체는 자식 코루틴으로 supervisorScope 함수에 의해 생성된 SupervisorJob 객체를 가진다. SupervisorJob 객체는
  다시 Coroutine1의 Job과 Coroutine2의 Job을 자식 코루틴으로 가지며, Coroutine1은 Coroutine3 코루틴을 자식 코루틴으로 가진다.

  <img width="600" alt="image" src="https://github.com/user-attachments/assets/ee0694a9-c81d-4784-b2dd-38e27cc07604" />

- 만약 Coroutine3에서 예외가 발생하면 예외는 Coroutine1까지만 전파되고 supervisorScope의 SupervisorJob 객체로는 전파되지 않는다.

  <img width="800" alt="image" src="https://github.com/user-attachments/assets/2ac9d934-5701-402f-ab08-0fa1e36150e6" />

- 이처럼 supervisorScope를 사용하면 구조화도 깨지 않으면서 자식 코루틴의 예외 전파도 제한할 수 있다. 지금까지 예외 전파를 제한하는 방법에 대해 알아봤으면, 이제 예외를 처리하는 방법에 대해 알아보자

## 8.3. CoroutineExceptionHandler를 사용한 예외 처리

### 8.3.1. CoroutineExceptionHandler 생성

- CoroutineExceptionHandler 객체는 CoroutineExceptionHandler 함수를 통해 생성할 수 있다.

    ```kotlin
    public inline fun CoroutineExceptionHandler(crossinline handler: (CoroutineContext, Throwable) -> Unit): CoroutineExceptionHandler =
        object : AbstractCoroutineContextElement(CoroutineExceptionHandler), CoroutineExceptionHandler {
            override fun handleException(context: CoroutineContext, exception: Throwable) =
                handler.invoke(context, exception)
        }
    ```

    ```kotlin
    val exceptionHandler =
    	  CoroutineExceptionHandler { coroutineContext, throwable ->
    	      println("[예외 발생] $throwable")
    	  }
    ```

### 8.3.2. CoroutineExceptionHandler 사용

- 생성된 CoroutineExceptionHandler 객체는 CoroutineContext 객체의 구성 요소로 포함될 수 있다.

    ```kotlin
    fun main(): Unit =
        runBlocking {
            val exceptionHandler =
                CoroutineExceptionHandler { coroutineContext, throwable ->
                    println("[예외 발생] $throwable")
                }
            CoroutineScope(exceptionHandler).launch(CoroutineName("Coroutine1")) {
                launch(CoroutineName("Coroutine2")) {
                    throw Exception("Coroutine2에 예외가 발생했습니다")
                }
            }
            delay(1000L)
        }
    ```

  > [예외 발생] java.lang.Exception: Coroutine2에 예외가 발생했습니다

>

- CoroutineScope의 인자로 CoroutineExceptionHandler가 들어가며, 이를 통해 생성된 CoroutineScope를 사용해 launch 함수가 호출돼 Coroutine1 코루틴이
  실행된다.
- **CoroutineScope 함수가 호출되면 기본적으로 Job 객체가 새로 생성**되므로, runBlocking이 호출돼 만들어지는 Job 객체와의 구조화가 깨지며, Coroutine1 코루틴은
  CoroutineScope 객체로부터 CoroutineContext를 상속받아 exceptionHandler가 상속된다. 또한, Coroutine2 코루틴도 Coroutine1 코루틴으로부터
  exceptionHandler를 상속받는다.

  <img width="660" alt="image" src="https://github.com/user-attachments/assets/87534005-66c8-43c1-9432-653370065d46" />

- exceptionHandler는 Coroutine1, Coroutine2, CoroutineScope 객체에 모두 설정되어 있다. 그렇다면 셋 중 어디에 설정된 exceptionHandler가 예외를 처리한
  것일까?

### 8.3.3. 처리되지 않은 예외만 처리하는 CoroutineExceptionHandler

- CoroutineExceptionHandler 객체는 처리되지 않은 예외만 처리한다. 만약 자식 코루틴이 부모 코루틴으로 예외를 전파하면, 자식 코루틴에서는 예외가 처리된 것으로 보아 자식 코루틴에 설정된
  CoroutineExceptionHandler 객체는 동작하지 않는다.

    ```kotlin
    fun main() =
        runBlocking {
            val exceptionHandler =
                CoroutineExceptionHandler { coroutineContext, throwable ->
                    println("[예외 발생] $throwable")
                }
            CoroutineScope(Dispatchers.IO).launch(CoroutineName("Coroutine1")) {
                launch(CoroutineName("Coroutine2") + exceptionHandler) {
                    throw Exception("Coroutine2에 예외가 발생했습니다")
                }
            }
            delay(1000L)
        }
    ```

    - exceptionHandler를 CoroutineScope에 설정하는 대신 Coroutine2에 설정한다.

      <img width="660" alt="image" src="https://github.com/user-attachments/assets/00857385-5606-4e40-bdd8-21392086cb89" />

    - Corotuine2에서 예외가 발생하므로, Corotuine2 코루틴에 설정된 exceptionHandler가 예외를 처리할 것 처럼 보이지만, 코드를 실행하면 오류 로그만 출력된다.

      <img width="800" alt="image" src="https://github.com/user-attachments/assets/63cbad69-2795-4598-bc3f-41981321f5cb" />

    - 그 이유는 Corotuine2가 Coroutine1으로 예외를 전파했기 때문이다. <b>launch 코루틴은 다른 launch 코루틴으로 예외를 전파하면 예외를 처리한 것으로 보며</b>,
      CoroutineExceptionHandler 객체는 이미 처리된 예외에 대해서는 동작하지 않는다.
- 따라서 구조화된 코루틴 상에 여러 CoroutineExceptionHandler 객체가 설정돼 있더라도, <b>예외를 마지막으로 처리하는 위치에 설정된 CoroutineExceptionHandler 객체만 예외를
  처리</b>한다. 이런 특징으로 인해 CoroutineExceptionHandler 객체는 ‘공통 예외 처리기’로서 동작할 수 있다.
- 그렇다면, 예외를 마지막으로 처리하는 위치는 어디일까? 바로 launch 함수로 생성된 코루틴 중 최상위에 있는 코루틴이다.

### 8.3.4. CoroutineExceptionHandler의 예외 처리 위치

- 8.3.2에서 본 코드를 다시 보자

    ```kotlin
    fun main(): Unit =
        runBlocking {
            val exceptionHandler =
                CoroutineExceptionHandler { coroutineContext, throwable ->
                    println("[예외 발생] $throwable")
                }
            CoroutineScope(exceptionHandler).launch(CoroutineName("Coroutine1")) {
                launch(CoroutineName("Coroutine2")) {
                    throw Exception("Coroutine2에 예외가 발생했습니다")
                }
            }
            delay(1000L)
        }
    ```

    - 이곳에 설정된 CoroutineExceptionHandler 객체가 동작할 수 있었던 이유는 launch 함수로 생성된 코루틴 중 최상위에 있는 Coroutine1에
      CoroutineExceptionHandler가 설정되어 있기 때문이다.

      <img width="660" alt="image" src="https://github.com/user-attachments/assets/d9bcdda7-b61d-4b26-a0f9-02635b27439f" />

    - 즉, 위 그림에서 화살표로 표시된 launch 코루틴 중 최상위에 있는 Coroutine1 코루틴에 설정된 CoroutineExceptionHandler 객체만 동작해 예외가 출력된다.

- 이를 확인하기 위해 코드를 아래와 같이 변경해보자.

    ```kotlin
    fun main() =
        runBlocking {
            val exceptionHandler =
                CoroutineExceptionHandler { coroutineContext, throwable ->
                    println("[예외 발생] $throwable")
                }
    
            val exceptionHandler2 =
                CoroutineExceptionHandler { coroutineContext, throwable ->
                    println("[예외 발생2] $throwable")
                }
            CoroutineScope(Dispatchers.IO + exceptionHandler)
                .launch(CoroutineName("Coroutine1") + exceptionHandler2) {
                    launch(CoroutineName("Coroutine2")) {
                        throw Exception("Coroutine2에 예외가 발생했습니다")
                    }
                }
            delay(1000L)
        }
    ```

    - 이 코드에서는 예외 발생 시 [예외 발생2]로 시작하는 문구를 출력하는 exceptionHandler2를 추가로 만든 후 Coroutine1과 함께 exceptionHandler2를 설정했다.

      <img width="660" alt="image" src="https://github.com/user-attachments/assets/e822780c-02ba-4b75-8a4b-b0ee4228fd43" />

    - 이런 구조에서는 Coroutine1이나 Coroutine2에서 예외 발생 시, launch 코루틴 중 최상위에 있는 Coroutine1 코루틴에 설정된 exceptionHandler2가 동작한다.

  > [예외 발생2] java.lang.Exception: Coroutine2에 예외가 발생했습니다
    - 최상위 launch 코루틴인 Coroutine1에 설정된 exceptionHandler2가 예외를 처리한 것을 볼 수 있다.

### 8.3.5. CoroutineExceptionHandler를 사용해야 하는 경우

- CoroutineExceptionHandler의 handleException 함수가 호출될 때는 이미 해당 예외로 인해 코루틴이 완료된 상태이기 때문에 CoroutineExceptionHandler를 사용해
  예외를 복구할 수는 없다.
- 그렇다면 CoroutineExceptionHandler는 언제 사용될까? 바로 예외를 로깅하거나, 오류 메시지를 표시하기 위해 구조화된 코루틴들에 공통으로 동작하는 예외 처리기를 설정해야 하는 경우 사용된다.

    ```kotlin
    fun main(): Unit =
        runBlocking {
            val exceptionHandler =
                CoroutineExceptionHandler { coroutineContext, throwable ->
                    println("[예외 로깅] $throwable")
                }
    
            CoroutineScope(Dispatchers.IO)
                .launch(CoroutineName("Coroutine1") + exceptionHandler) {
                    launch(CoroutineName("Coroutine2")) {
                        throw Exception("Coroutine2에 예외가 발생했습니다")
                    }
                    launch(CoroutineName("Coroutine3")) {
                        // 다른 작업
                    }
                }
            delay(1000L)
        }
    ```

    - 이 코드에서는 Coroutine1이 작업의 시작점 역할을 하고 Coroutine2 코루틴과 Coroutine3을 자식으로 가진다. 이런 경우 Coroutine1 코루틴 하위의 코루틴에 뭔가 문제가 생겼을
      경우 로깅이 필요하다면 Coroutine1에 예외를 로깅하는 CoroutineExceptionHandler를 설정하면 된다.

      <img width="660" alt="image" src="https://github.com/user-attachments/assets/4c1a14c3-e86c-470c-bf30-324178b283ee" />

  > [예외 로깅] java.lang.Exception: Coroutine2에 예외가 발생했습니다
    - Coroutine2에 발생한 예외가 Coroutine1에 설정된 exceptionHandler에 의해 처리돼 결과가 나오는 것을 볼 수 있다.

### 8.3.6. CoroutineExceptionHandler는 예외 전파를 제한하지 않는다

- CoroutineExceptionHandler 사용 시 많이 하는 실수는 CoroutineExceptionHandler가 try catch문처럼 동작해 예외 전파를 제한한다고 생각하는 것이다. 하지만,
  CoroutineExceptionHandler는 예외가 마지막으로 처리되는 위치에서 예외를 처리할 뿐, 예외 전파를 제한하지 않는다.

    ```kotlin
    fun main(): Unit =
        runBlocking {
            val exceptionHandler =
                CoroutineExceptionHandler { coroutineContext, throwable ->
                    println("[예외 발생] $throwable")
                }
            launch(CoroutineName("Coroutine1") + exceptionHandler) {
                throw Exception("Coroutine1에 예외가 발생했습니다")
            }
        }
    ```

  <img width="800" alt="image" src="https://github.com/user-attachments/assets/26aaa407-d601-4ad9-9695-f644844f5ebd" />

- Coroutine1 코루틴에 CoroutineExceptionHandler 객체가 설정된 상태에서 Coroutine1 코루틴에 예외가 발생한다. 하지만 Coroutine1에서 발생한 예외는 runBlocking
  코루틴으로 전파된다. 즉, CoroutineExceptionHandler 객체는 예외 전파를 제한하지 않는다.

  <img width="600" alt="image" src="https://github.com/user-attachments/assets/22217973-1979-4a2b-a5d1-c95c3cfa8ddd" />

## 8.4. try-catch 문을 사용한 예외 처리

### 8.4.1. try-catch 문을 사용해 코루틴 예외 처리하기

- 코틀린에서 일반적으로 예외를 처리하는 방식과 같이 try-catch문을 통해 코루틴 예외를 처리할 수 있다.

    ```kotlin
    fun main(): Unit =
        runBlocking {
            launch(CoroutineName("Coroutine1")) {
                try {
                    throw Exception("Coroutine1에 예외가 발생했습니다")
                } catch (e: Exception) {
                    println(e.message)
                }
            }
            launch(CoroutineName("Coroutine2")) {
                delay(100L)
                println("Coroutine2 실행 완료")
            }
        }
    ```

  > Coroutine1에 예외가 발생했습니다 <br>
  Coroutine2 실행 완료
    - 위 코드에서는 Coroutine1에서 예외가 발생하지만, try-catch문을 통해 예외가 처리되고 있기 때문에 부모 코루틴인 runBlocking으로 예외가 전파되지 않는다. runBlocking으로
      예외가 전파되지 않아 Coroutine2도 정상적으로 실행되는 것을 볼 수 있다.

### 8.4.2 코루틴 빌더 함수에 대한 try-catch문은 코루틴의 예외를 잡지 못한다

- try-catch문 사용 시 많이 하는 실수는 try-catch문을 코루틴 빌더 함수에 사용하는 것이다. 코루틴 빌더 함수에 try-catch문을 사용하면 코루틴에서 발생한 예외가 잡히지 않는다.

    ```kotlin
    fun main() =
        runBlocking<Unit> {
            try {
                launch(CoroutineName("Coroutine1")) {
                    throw Exception("Coroutine1에 예외가 발생했습니다")
                }
            } catch (e: Exception) {
                println(e.message)
            }
            launch(CoroutineName("Coroutine2")) {
                delay(100L)
                println("Coroutine2 실행 완료")
            }
        }
    ```

  > Exception in thread "main" java.lang.Exception: Coroutine1에 예외가 발생했습니다
    - Coroutine1을 만드는 launch 코루틴 빌더 함수를 try-catch문으로 감싸지만 이 try-catch문은 Coroutine1 코루틴에서 발생하는 예외를 잡지 못한다.
    - launch는 코루틴을 생성하는 데 사용되는 함수일 뿐이므로 람다식의 실행은 생성된 코루틴이 CoroutineDispatcher에 의해 스레드로 분배되는 시점에 일어나기 때문이다.
    - 즉, 이 try-catch문은 launch 코루틴 빌더 함수 자체의 실행만 체크하며, 람다식은 예외 처리 대상이 아니다.
- 코루틴에 대한 예외 처리를 위해서는 코루틴 빌더 함수의 람다식 내부에서 try-catch문을 사용해야 한다는 점을 명심하고 코루틴 빌더 함수에 try-catch문을 사용하지 않도록 주의하자!

## 8.5. async의 예외 처리

### 8.5.1. async의 예외 노출

- async 코루틴 빌더 함수는 다른 코루틴 빌더 함수와 달리 결괏값을 Deferred 객체로 감싸고 await 호출 시점에 결괏값을 노출한다. 이런 특성 때문에 코루틴 실행 도중 예외가 발생해 결괏값이 없다면
  Deferred에 대한 await 호출 시 예외가 노출된다.

    ```kotlin
    fun main() =
        runBlocking<Unit> {
            supervisorScope {
                val deferred: Deferred<String> =
                    async(CoroutineName("Coroutine1")) {
                        throw Exception("Coroutine1에 예외가 발생했습니다")
                    }
                try {
                    deferred.await()
                } catch (e: Exception) {
                    println("[노출된 예외] ${e.message}")
                }
            }
        }
    ```

    - supervisorScope를 사용해 예외가 전파되지 않도록 만들며, 내부에서 async 코루틴 빌더 함수를 통해 Coroutine1을 실행하고, 그로부터 생성되는 Deferred<String> 타입의
      객체를 deferred로 참조한다. Coroutine1에서는 예외가 발생하므로 deferred에 대해 await를 호출하면 코루틴에서 발생한 예외가 외부로 노출되는데 이의 처리를 위해
      try-catch문으로 deferred.await()를 감싼다.

  > [노출된 예외] Coroutine1에 예외가 발생했습니다


- 이처럼 async 코루틴 빌더를 호출해 만들어진 코루틴에서 예외가 발생하는 경우에 await 호출부에서 예외 처리가 될 수 있도록 해야 한다.

### 8.5.2. async의 예외 전파

- async 코루틴 빌더 함수 사용 시 많이 하는 실수 중 하나는 await 함수 호출부에서만 예외 처리를 하는 것이다. async 코루틴 빌더 함수도 예외가 발생하면 부모 코루틴으로 예외를 전파하는데 이를
  적절하게 처리해야 한다.

    ```kotlin
    fun main(): Unit =
        runBlocking {
            async(CoroutineName("Coroutine1")) {
                throw Exception("Coroutine1에 예외가 발생했습니다")
            }
            launch(CoroutineName("Coroutine2")) {
                delay(100L)
                println("[${Thread.currentThread().name}] 코루틴 실행")
            }
        }
    ```

  > Exception in thread "main" java.lang.Exception: Coroutine1에 예외가 발생했습니다
    - async를 사용해 만든 Coroutine1에서 예외를 발생시킨다. Coroutine1에 await를 호출하는 부분이 없음에도 실행해보면 예외 로그가 출력된다.
    - 그 이유는 Coroutine1에서 발생한 예외가 부모 코루틴으로 전파돼 부모 코루틴을 취소시키기 때문이다. 따라서, 나머지 자식 코루틴 Coroutine2도 자동으로 취소된다.
- 이를 해결하기 위해서는 Coroutine1 코루틴에서 발생한 예외가 부모 코루틴으로 전파되지 않도록 만들어야 한다. 8.5.1에서 본 코드처럼 supervisorJob을 사용해 예외 전파를 제한시킬 수 있다.
- 따라서, async 코루틴 빌더를 사용할 때는 전파되는 예외와 await 호출 시 노출되는 예외를 모두 처리해 줘야 함을 명심하자!

## 8.6. 전파되지 않는 예외

### 8.6.1. 전파되지 않는 CancellationException

- 코루틴은 CancellationException 예외가 발생해도 부모 코루틴으로 전파되지 않는다.

    ```kotlin
    fun main() =
        runBlocking(CoroutineName("runBlocking 코루틴")) {
            launch(CoroutineName("Coroutine1")) {
                launch(CoroutineName("Coroutine2")) {
                    throw CancellationException()
                }
                delay(100L)
                println("[${Thread.currentThread().name}] 코루틴 실행")
            }
            delay(100L)
            println("[${Thread.currentThread().name}] 코루틴 실행")
        }
    ```

  > [main @runBlocking 코루틴#1] 코루틴 실행<br>
  [main @Coroutine1#2] 코루틴 실행
    - Coroutine2에서 예외가 발생했지만 CancellationException이므로 부모로 전파되지 않는다. 따라서 실행 결과를 보면 runBlocking, Coroutine1이 정상적으로 실행되는 것을
      볼 수 있다.

      <img width="600" alt="image" src="https://github.com/user-attachments/assets/bf0c965e-ca23-49ae-b575-43113ec1ac56" />

### 8.6.2. 코루틴 취소시 사용되는 JobCancellationException

- 그렇다면 코루틴은 왜 CancellationException을 부모 코루틴으로 전파하지 않는 것일까? CancellationException은 코루틴의 취소에 사용되는 특별한 예외이기 때문이다. Job 객체에
  대해 cancel 함수를 호출하면 CancellationException의 서브 클래스인 JobCancellationException을 발생시켜 코루틴을 취소시킨다.

  <img width="800" alt="image" src="https://github.com/user-attachments/assets/219b174e-7ec7-4d79-a359-9a3cf409a175" />

    ```kotlin
    fun main() =
        runBlocking {
            val job =
                launch {
                    delay(1000L) // 1초간 지속
                }
            job.invokeOnCompletion { exception ->
                println(exception) // 발생한 예외 출력
            }
            job.cancel() // job 취소
        }
    ```

  > kotlinx.coroutines.JobCancellationException: StandaloneCoroutine was cancelled;<br>
  job=StandaloneCoroutine{Cancelled}@5cbc508c

- CancellationException은 특정 코루틴만 취소하는 데 사용되며, 코루틴 코드 상에서 다양하게 응용돼 사용된다.
- job.invokeOnCompletion?
    - `invokeOnCompletion`은 코루틴이<b>종료될 때 호출할 콜백</b>을 등록하는 함수입니다. 이 콜백은**정상 종료든 예외 종료든 또는`cancel()`로 인해 취소되든**무조건 호출됩니다.

### 8.6.3. withTimeOut 사용해 코루틴의 실행 시간 제한하기

- 코루틴 라이브러리는 제한 시간을 두고 작업을 실행할 수 있도록 만드는 withTimeOut 함수를 제공한다.

    ```kotlin
    /**
    지정된 타임아웃이 있는 코루틴 내에서 주어진 일시 정지 코드 블록을 실행하고, 타임아웃이 초과된 경우 TimeoutCancellationException을 발생시킵니다.
    주어진 시간 Millis가 양수가 아닌 경우, TimeoutCancellationException이 즉시 적용됩니다.
    
    블록 내에서 실행 중인 코드는 타임아웃 시 cancelled되며, 블록 내에서 cancellable suspending function의 활성화 또는 다음 호출 시 TimeoutCancellationException이 발생합니다.
    타임아웃 시 예외를 적용하지 않는 sibling 함수는 withTimeoutOrNull입니다.
    
    시간 초과 명령은 onTimeout clause(절)을 사용하여 선택된 호출에 대해 지정할 수 있습니다.
    
    타임아웃 이벤트는 블록에서 실행 중인 코드와 비동기적이며, 타임아웃 블록 내부에서 반환되기 직전이라도 언제든지 발생할 수 있습니다.
    
    블록 내부에서 닫히거나 블록 외부에서 해제해야 하는 리소스를 열거나 확보하는 경우 이 점을 염두에 두세요.
    
    자세한 내용은 코루틴 가이드의 비동기 타임아웃 및 리소스 [https://kotlinlang.org/docs/reference/coroutines/cancellation-and-timeouts.html#asynchronous-timeout-and-resources ] 섹션을 참조하세요.
    Implementation note: 시간이 정확히 추적되는 방식은 컨텍스트의 CoroutineDispatcher의 구현 세부 사항입니다.
    
    매개변수:
    timeMillis - 시간 초과 시간(밀리초).
    **/
    
    public suspend fun <T> withTimeout(timeMillis: Long, block: suspend CoroutineScope.() -> T): T {
        contract {
            callsInPlace(block, InvocationKind.EXACTLY_ONCE)
        }
        if (timeMillis <= 0L) throw TimeoutCancellationException("Timed out immediately")
        return suspendCoroutineUninterceptedOrReturn { uCont ->
            setupTimeout(TimeoutCoroutine(timeMillis, uCont), block)
        }
    }
    ```

- withTimeOut 함수는 매개변수로 실행 제한 시간을 밀리초 단위로 표현하는 timeMillis와 해당 시간 내에 실행되어야 할 작업인 block을 가진다. 작업이 주어진 시간 내에 완료되지 않으면
  TimeoutCancellationException을 발생시키는데 TimeoutCancellationException은 CancellationException의 서브 클래스이다. 따라서,
  TimeoutCancellationException이 발생되더라도 예외가 부모 코루틴으로 전파되지 않고 해당 예외가 발생한 코루틴만 취소된다.

    ```kotlin
    fun main(): Unit =
        runBlocking(CoroutineName("Parent Coroutine")) {
            launch(CoroutineName("Child Coroutine")) {
                withTimeout(1000L) {
                    // 실행 시간을 1초로 제한
                    delay(2000L) // 2초의 시간이 걸리는 작업
                    println("[${Thread.currentThread().name}] 코루틴 실행")
                }
            }
            delay(2000L)
            println("[${Thread.currentThread().name}] 코루틴 실행")
        }
    ```

  > [main @Parent Coroutine#1] 코루틴 실행

- Child 코루틴의 실행 시간을 1초로 제한시키고 내부에서 2초가 걸리는 작업을 실행한다. 따라서 withTimeOut은 TimeoutCancellationException을 발생시켜 Child
  Coroutine을 취소시키지만 예외는 Parent로 전파되지 않아 Parent Coroutine이 출력되는 것을 볼 수 있다.
- withTimeOut 함수는 실행 시간이 제한되어야 할 필요가 있는 다양한 작업에 사용된다. 대표적으로 네트워크 호출의 실행 시간을 제한하는 데 사용할 수 있다.
- withTimeOutOrNull 함수를 사용하면 TimeoutCancellationException이 발생되지 않고(코루틴이 취소되지 않고) null이 반환된다.