# 예외 처리
코루틴의 비동기 작업은 네트워크 요청이나 데이터 베이스 작업 같은 입출력 작업을 수행하는 데 쓰이는 경우가 많아 예측할 수 없는 예외가 발생할 가능성이 높다.

코루틴에 대한 적절한 예외 처리는 안정적인 애플리케이션을 만드는 데 필수적이다.

## 코루틴의 예외 전파
### 코루틴에서 예외가 전파되는 방식
코루틴 실행 도중 예외가 발생하면 예외가 발생한 코루틴은 취소되고 부모 코루틴으로 예외가 전파된다.

부모 코루틴에서 예외가 처리되지 않으면 예외는 다시 상위 코루틴으로 전파된다.

상위 코루틴으로 예외가 전파되는 것이 반복되면 최상위 코루틴인 루트 코루틴까지 예외가 전파될 수 있다.

코루틴의 특성에 따라 해당 코루틴의 하위에 있는 모든 코루틴에게 취소가 전파된다.

-> 예외는 부모 코루틴 방향으로만 전파된다.

-> 코루틴의 예외 전파를 제대로 막지 못해 루트 코루틴이 취소되면 구조화된 코루틴이 모두 취소될 수 있다.

작은 작업에서 발생한 예외로 인해 큰 작업이 취소되면 애플리케이션의 안정성에 문제가 생길 수 있다.

```
fun main() = runBlocking<Unit> {
  launch(CoroutineName("Coroutine1")) {
    launch(CoroutineName("Coroutine3")) {
      throw Exception("예외 발생")
    }
    delay(100L)
    println("[${Thread.currentThread().name}] 코루틴 실행")
  }
  launch(CoroutineName("Coroutine2")) {
    delay(100L)
    println("[${Thread.currentThread().name}] 코루틴 실행")
  }
  delay(1000L)
}
```

이런 문제 해결을 위해 코루틴은 예외 전파를 제한하는 방법이 있다.

## 예외 전파 제한
1. 코루틴의 구조화를 깨는 방법
2. SupervisorJob 객체를 사용하여 예외 전파를 제한하는 방법
3. SupervisorScope 함수를 사용하는 방법

### Job 객체를 사용한 예외 전파 제한
#### Job 객체를 사용해 예외 전파 제한하기
코루틴은 자신의 부모 코루틴으로만 예외를 전파하는 특성을 가지므로 부모 코루틴과의 구조화를 깬다면 예외가 전파되지 않는다.

Job()을 사용해 새로운 Job 객체를 부모 Job으로 설정함으로써 Parent Coroutine 코루틴과의 구조화를 깰 수 있다.

```
fun main() = runBlocking<Unit> {
  launch(CoroutineName("Parent Coroutine")) {
    launch(CoroutineName("Coroutine1") + Job()) { // 새로운 Job 객체를 만들어 Coroutine1에 연결
      launch(CoroutineName("Coroutine3")) {
        throw Exception("예외 발생")
      }
      delay(100L)
      println("[${Thread.currentThread().name}] 코루틴 실행")
    }
    launch(CoroutineName("Coroutine2")) {
      delay(100L)
      println("[${Thread.currentThread().name}] 코루틴 실행")
    }
  }
  delay(1000L)
}
/*
// 결과:
Exception in thread "main" java.lang.Exception: 예외 발생
	at chapter8.code2.Code8_2Kt$main$1$1$1$1.invokeSuspend(Code8-2.kt:9)
	at kotlin.coroutines.jvm.internal.BaseContinuationImpl.resumeWith(ContinuationImpl.kt:33)
	...
[main @Coroutine2#4] 코루틴 실행

Process finished with exit code 0
*/
```

#### Job 객체를 사용한 예외 전파 제한의 한계
Job 객체를 생성해 코루틴의 구조화를 깨는 것은 예외 전파를 제한하는 것뿐만 아니라 취소 전파도 제한시킨다.

코루틴은 큰 작업과 관련된 작은 작업으로 나누는 과정을 통해 일어난다.

만약 작은 작업의 구조화가 깨진다면 큰 작업에 취소가 요청되더라도 작은 작업은 취소되지 않으며 이는 비동기 작업을 불안정하게 만든다.

코루틴의 구조화는 큰 작업을 연관된 작은 작업으로 나누는 방식으로 일어나기 대문에 안정적으로 동작하기 위해서는 Parent Coroutine 코루틴이 취소되면 자식 코루틴들도 함께 취소되어야 한다.

하지만 예외 전파 방지를 위해 새로운 Job 객체를 사용하면 구조화가 깨져 버려 이 두 자식 코루틴들이 정상 실행된다.

```
fun main() = runBlocking<Unit> {
  val parentJob = launch(CoroutineName("Parent Coroutine")) {
    launch(CoroutineName("Coroutine1") + Job()) {
      launch(CoroutineName("Coroutine3")) { // Coroutine3에서 예외 제거
        delay(100L)
        println("[${Thread.currentThread().name}] 코루틴 실행")
      }
      delay(100L)
      println("[${Thread.currentThread().name}] 코루틴 실행")
    }
    launch(CoroutineName("Coroutine2")) {
      delay(100L)
      println("[${Thread.currentThread().name}] 코루틴 실행")
    }
  }
  delay(20L) // 코루틴들이 모두 생성될 때까지 대기
  parentJob.cancel() // Parent Coroutine에 취소 요청
  delay(1000L)
}
/*
// 결과:
[main @Coroutine1#3] 코루틴 실행
[main @Coroutine3#5] 코루틴 실행

Process finished with exit code 0
*/
```

### SupervisorJob 객체를 사용한 예외 전파 제한
#### SupervisorJob 객체를 사용해 예외 전파 제한하기
SupervisorJob 객체는 자식 코루틴으로부터 예외를 전파받지 않는 특수한 Job 객체이다.

하나의 자식 코루틴에서 발생한 예외가 다른 자식 코루틴에게 영향을 미치지 못하도록 만드는 데 사용된다.

```
fun main() = runBlocking<Unit> {
  val supervisorJob = SupervisorJob()
  launch(CoroutineName("Coroutine1") + supervisorJob) {
    launch(CoroutineName("Coroutine3")) {
      throw Exception("예외 발생")
    }
    delay(100L)
    println("[${Thread.currentThread().name}] 코루틴 실행")
  }
  launch(CoroutineName("Coroutine2") + supervisorJob) {
    delay(100L)
    println("[${Thread.currentThread().name}] 코루틴 실행")
  }
  delay(1000L)
}
/*
// 결과:
Exception in thread "main" java.lang.Exception: 예외 발생
	at chapter8.code4.Code8_4Kt$main$1$1$1.invokeSuspend(Code8-4.kt:9)
	at kotlin.coroutines.jvm.internal.BaseContinuationImpl.resumeWith(ContinuationImpl.kt:33)
	...
[main @Coroutine2#3] 코루틴 실행

Process finished with exit code 0
*/
```

문제점: SupervisorJob 객체가 runBlocking이 호출돼 만들어진 Job 객체와의 구조화를 깬다.

### 코루틴의 구조화를 깨지 않고 SupervisorJob 사용하기
구조화를 깨지 않고 SupervisorJob을 사용하기 위해서는 SupervisorJob의 인자로 부모 Job 객체를 넘기면 된다.

```
fun main() = runBlocking<Unit> {
  // supervisorJob의 parent로 runBlocking으로 생성된 Job 객체 설정
  val supervisorJob = SupervisorJob(parent = this.coroutineContext[Job])
  launch(CoroutineName("Coroutine1") + supervisorJob) {
    launch(CoroutineName("Coroutine3")) {
      throw Exception("예외 발생")
    }
    delay(100L)
    println("[${Thread.currentThread().name}] 코루틴 실행")
  }
  launch(CoroutineName("Coroutine2") + supervisorJob) {
    delay(100L)
    println("[${Thread.currentThread().name}] 코루틴 실행")
  }
  supervisorJob.complete() // supervisorJob 완료 처리
}
/*
// 결과:
Exception in thread "main" java.lang.Exception: 예외 발생
	at chapter8.code5.Code8_5Kt$main$1$1$1.invokeSuspend(Code8-5.kt:9)
	at kotlin.coroutines.jvm.internal.BaseContinuationImpl.resumeWith(ContinuationImpl.kt:33)
	...
[main @Coroutine2#3] 코루틴 실행

Process finished with exit code 0
*/
```

this.coroutineContext[Job]을 사용해 runBlocking이 호출돼 만들어진 Job 객체를 가져오며, SupervisorJob 생성 함수의 인자로 이 Job 객체를 넘기고 마지막에 supervisorJob.complete()을 실행해 명시적으로 완료 처리를 한다.

### SupervisorJob을 CoroutineScope와 함께 사용하기
CoroutineScpoe의 CoroutineContext에 SupervisorJob 객체가 설정된다면 CoroutineScope의 자식 코루틴에서 발생하는 예외가 다른 자식 코루틴으로 전파되지 않는다.

```
fun main() = runBlocking<Unit> {
  val coroutineScope = CoroutineScope(SupervisorJob())
  coroutineScope.apply {
    launch(CoroutineName("Coroutine1")) {
      launch(CoroutineName("Coroutine3")) {
        throw Exception("예외 발생")
      }
      delay(100L)
      println("[${Thread.currentThread().name}] 코루틴 실행")
    }
    launch(CoroutineName("Coroutine2")) {
      delay(100L)
      println("[${Thread.currentThread().name}] 코루틴 실행")
    }
  }
  delay(1000L)
}
/*
// 결과:
Exception in thread "DefaultDispatcher-worker-1" java.lang.Exception: 예외 발생
	at chapter8.code6.Code8_6Kt$main$1$1$1$1.invokeSuspend(Code8-6.kt:10)
	at kotlin.coroutines.jvm.internal.BaseContinuationImpl.resumeWith(ContinuationImpl.kt:33)
	...
[DefaultDispatcher-worker-1 @Coroutine2#3] 코루틴 실행

Process finished with exit code 0
*/
```

#### SupervisorJob을 사용할 때 흔히 하는 실수
예외 전파 방지를 위해 코루틴 빌더 함수의 context 인자에 SupervisorJob()을 넘기고, 코루틴 빌더 함수가 호출돼 생성되는 ㅣ코루틴의 하위에 자식 코루틴들을 생성하는 것.

 launch 함수는 context 인자에 Job 객체가 입력될 경우 해당 Job 객체를 부모로 하는 새로운 Job 객체를 만들기 때문이다.

-> launch 함수에 SupervisorJob 객체를 부모로 하는 새로운 Job 객체가 만들어진다.

예외가 발생해도 Parent Coroutine까지 전파돼 해당 코루틴이 취소되고 다른 자식 코루틴도 취소된다.

-> Parent Coroutine 코루틴의 예외가 Supervisor 객체로 전파되지는 않지만 아무런 역할을 하지 못한다.

SupervisorJob 객체가 Job 계층 구조의 어떤 위치에 있어야 하는지 충분히 고민하고 사용하자.

```
fun main() = runBlocking<Unit> {
  launch(CoroutineName("Parent Coroutine") + SupervisorJob()) {
    launch(CoroutineName("Coroutine1")) {
      launch(CoroutineName("Coroutine3")) {
        throw Exception("예외 발생")
      }
      delay(100L)
      println("[${Thread.currentThread().name}] 코루틴 실행")
    }
    launch(CoroutineName("Coroutine2")) {
      delay(100L)
      println("[${Thread.currentThread().name}] 코루틴 실행")
    }
  }
  delay(1000L)
}
/*
// 결과:
Exception in thread "main" java.lang.Exception: 예외 발생
	at chapter8.code7.Code8_7Kt$main$1$1$1$1.invokeSuspend(Code8-7.kt:9)
	at kotlin.coroutines.jvm.internal.BaseContinuationImpl.resumeWith(ContinuationImpl.kt:33)
	...

Process finished with exit code 0
*/
```

### supervisorScope를 사용한 예외 전파 제한
supervisorScope 함수는 SupervisorJob 객체를 가진 CoroutineScope 객체를 생성하며, 이 SupervisorJob 객체는 supervisorScope 함수를 호출한 코루틴의 Job 객체를 부모로 가진다

-> supervisorScope 함수를 사용하면 복잡한 설정 없이도 구조화를 깨지 않고 예외 전파를 제한할 수 있다.

supervisorScope 내부에서 실행되는 코루틴은 SupervisorJob과 부모-자식 관계로 구조화된다.

supervisorScope의 SupervisorJob 객체는 코드가 모두 실행되고 자식 코루틴도 모두 실행 완료되면 자동으로 완료 처리된다.

```
fun main() = runBlocking<Unit> {
  supervisorScope {
    launch(CoroutineName("Coroutine1")) {
      launch(CoroutineName("Coroutine3")) {
        throw Exception("예외 발생")
      }
      delay(100L)
      println("[${Thread.currentThread().name}] 코루틴 실행")
    }
    launch(CoroutineName("Coroutine2")) {
      delay(100L)
      println("[${Thread.currentThread().name}] 코루틴 실행")
    }
  }
}
/*
// 결과:
Exception in thread "main" java.lang.Exception: 예외 발생
	at chapter8.code8.Code8_8Kt$main$1$1$1$1.invokeSuspend(Code8-8.kt:9)
	at kotlin.coroutines.jvm.internal.BaseContinuationImpl.resumeWith(ContinuationImpl.kt:33)
	...
[main @Coroutine2#3] 코루틴 실행

Process finished with exit code 0
*/
```

## CoroutineExceptionHandler를 사용한 예외 처리
구조화된 코루틴들에 공통적인 예외 처리기를 설정해야 하는 경우 CoroutineContext 구성 요소로 CoroutineExceptionHandler라는 예외 처리기를 사용할 수 있다.

### CoroutineExceptionHandler 생성
CoroutineExceptionHandler 객체는 CoroutineExceptionHandle 함수를 통해 생성할 수 있다.

CoroutineExceptionHandler 함수는 예외를 처리하는 람다식인 handler를 매개변수로 가진다.

handler는 CoroutineContext와 Throwable 타입의 매개변수를 갖는 람다식으로 이 람다식에 예외가 발생했을 때 어떤 동작을 할지 입력해 예외를 처리할 수 있다.

### CoroutineExceptionHandler 사용
```
fun main() = runBlocking<Unit> {
  val exceptionHandler = CoroutineExceptionHandler { coroutineContext, throwable ->
    println("[예외 발생] ${throwable}")
  }
  CoroutineScope(exceptionHandler).launch(CoroutineName("Coroutine1")) {
    throw Exception("Coroutine1에 예외가 발생했습니다")
  }
  delay(1000L)
}
/*
// 결과:
[예외 발생] java.lang.Exception: Coroutine1에 예외가 발생했습니다
*/
```

### 처리되지 않은 예외만 처리하는 CoroutineExceptionHandle
CoroutineExceptionHandler 객체는 처리되지 않은 예외만 처리한다.

만약 자식 코루틴이 부모 코루틴으로 예외를 전파하면, 자식 코루틴에서는 예외가 처리된 것으로 보아 자식 코루틴에 설정된 CoroutineExceptionHandler 객체는 동작하지 않는다.

구조화된 코루틴 상에 여러 CoroutineExceptionHandler 객체가 설정돼 있더라도, 예외를 마지막으로 처리하는 위치에 설정된 CoroutineExceptionHandler 객체만 에외를 처리한다.

이런 특징으로 인해 CoroutineExceptionHandler 객체는 '공동 에외 처리기'로서 동작할 수 있다.

```
fun main() = runBlocking<Unit> {
  val exceptionHandler = CoroutineExceptionHandler { coroutineContext, throwable ->
    println("[예외 발생] ${throwable}")
  }
  launch(CoroutineName("Coroutine1") + exceptionHandler) {
    throw Exception("Coroutine1에 예외가 발생했습니다")
  }
  delay(1000L)
}
/*
// 결과:
Exception in thread "main" java.lang.Exception: Coroutine1에 예외가 발생했습니다
	at chapter8.code10.Main8_10Kt$main$1$1.invokeSuspend(Main8-10.kt:10)
	at kotlin.coroutines.jvm.internal.BaseContinuationImpl.resumeWith(ContinuationImpl.kt:33)
	...
*/
```

### CoroutineExceptionHandler의 예외 처리 위치
Coroutine1이나 Coroutine2에서 예외 발생 시, launch 코루틴 중 최상위에 있는 Coroutine1 코루틴에 설정된 exceptionHandler2가 동작한다.

-> 최상위 launch 코루틴인 Coroutine1에 설정된 exceptionHandler2가 예외를 처리한다.

### CoroutineExceptionHandler를 사용해야 하는 경우
CoroutineExceptionHandler의 handlerException 함수가 호출될 때는 이미 해당 예외로 인해 코루틴이 완료된 상태이다.

-> CoroutineExceptionHandler를 사용해 예외를 복구할 수는 없다.

CoroutineExceptionHandler는 언제 사용될까?

-> 예외를 로깅하거나, 오류 메시지를 표시하기 위해 구조화된 코루틴들에 공통으로 동작하는 예외 처리기를 설정해야 하는 경우

Coroutine1 코루틴이 작업의 시작점 역할을 하고, Coroutine2 코루틴과 Coroutine3 코루틴을 자식으로 가진다.

이런 경우, Coroutine1 코루틴 하위의 코루틴에 뭔가 문제가 생겼을 경우 로깅이 필요하다면 Coroutine1에 예외를 로깅하는 CoroutineExceptionHandler를 설정하면 된다.

### CoroutineExceptionHandler는 예외 전파를 제한하지 않는다
CoroutineExceptionHandler가 try-catch문처럼 동작해 예외 전파를 제한하는 것이 아니다.

CoroutineExceptionHandler는 예외가 마지막으로 처리되는 위치에서 예외를 처리할 뿐, 예외 전파를 제한하지 않는다.

-> CoroutineExceptionHandler 객체에는 예외 전파를 제한하는 기능이 없다.

```
fun main() = runBlocking<Unit> {
  val exceptionHandler = CoroutineExceptionHandler { coroutineContext, throwable ->
    println("[예외 발생] ${throwable}")
  }
  launch(CoroutineName("Coroutine1") + exceptionHandler) {
    throw Exception("Coroutine1에 예외가 발생했습니다")
  }
}
/*
// 결과:
Exception in thread "main" java.lang.Exception: Coroutine1에 예외가 발생했습니다
	at chapter8.code13.Main8_13Kt$main$1$1.invokeSuspend(Main8-13.kt:10)
*/
```

## try catch문을 사용한 예외 처리
### try catch문을 사용해 코루틴 예외 처리하기
이 코드에서는 Coroutine1 코루틴에서 예외가 발생하지만 예외가 try catch문을 통해 처리되고 있기 때문에 부모 코루틴인 runBlocking 코루틴으로 예외가 전파되지 않는다.

```
fun main() = runBlocking<Unit> {
  launch(CoroutineName("Coroutine1")) {
    try {
      throw Exception("Coroutine1에 예외가 발생했습니다")
    } catch (e: Exception) {
      println(e.message)
    }
  }
  launch(CoroutineName("Coroutine2")) {
    delay(100L)
    println("Coroutine2 실행 완료")
  }
}
/*
// 결과:
Coroutine1에 예외가 발생했습니다
Coroutine2 실행 완료
*/
```

### 코루틴 빌더 함수에 대한 try catch문은 코루틴의 예외를 잡지 못한다
try catch문은 launch 코루틴 빌더 함수 자체의 실행만 체크하며, 람다식은 예외 처리 대상이 아니다.

-> 예외가 runBlocking 코루틴으로 전파되며, 이는 Coroutine2 코루틴까지 취소시키고 프로세스가 비정상 종료되는 것을 볼 수 있다.

코루틴에 대한 예외 처리를 위해서는 코루틴 빌더 함수의 람다식 내부에서 try catch문을 사용해야 한다.

```
fun main() = runBlocking<Unit> {
  try {
    launch(CoroutineName("Coroutine1")) {
      throw Exception("Coroutine1에 예외가 발생했습니다")
    }
  } catch (e: Exception) {
    println(e.message)
  }
  launch(CoroutineName("Coroutine2")) {
    delay(100L)
    println("Coroutine2 실행 완료")
  }
}
/*
// 결과:
Exception in thread "main" java.lang.Exception: Coroutine1에 예외가 발생했습니다
	at chapter8.code15.Main8_15Kt$main$1$1.invokeSuspend(Main8-15.kt:8)
	at kotlin.coroutines.jvm.internal.BaseContinuationImpl.resumeWith(ContinuationImpl.kt:33)
	...

Process finished with exit code 1
*/
```

## async의 예외 처리
async 코루틴 빌더 함수는 결괏값을 Deferred 객체로 감싸고 await 호출 시점에 결괏값을 노출한다.

-> 코루틴 실행 도중 예외가 발생해 결괏값이 없다면 Deferred에 대한 await 호출 시 예외가 노출된다.

Coroutine1 코루틴 빌더를 호출해 만들어진 코루틴에서 예외가 발생할 경우에는 await 호출부에서 예외 처리가 될 수 있도록 해야 한다.

```
fun main() = runBlocking<Unit> {
  supervisorScope {
    val deferred: Deferred<String> = async(CoroutineName("Coroutine1")) {
      throw Exception("Coroutine1에 예외가 발생했습니다")
    }
    try {
      deferred.await()
    } catch (e: Exception) {
      println("[노출된 예외] ${e.message}")
    }
  }
}
/*
// 결과:
[노출된 예외] Coroutine1에 예외가 발생했습니다
*/
```

### async의 예외 전파
asycn 코루틴 빌더 함수 사용 시 많이 하는 실수
-> await 함수 호출부에서만 예외 처리를 하는 것

async 코루틴 빌더 함수도 예외가 발생하면 부모 코루틴으로 예외를 전파하는데 이를 적절하게 처리해야 한다.

Coroutine1 코루틴에서 발생한 예외가 부모 코루틴으로 전파돼 부모 코루틴을 취소시킨다.

나머지 자식 코루틴인 Coroutine2 코루틴 또한 자동으로 취소되기 때문에 Coroutine1 코루틴에서 발생한 예외가 부모 코루틴으로 전파되지 않도록 만들어야 한다.

supervisorScope를 사용해 예외 전파를 제한시킴으로써 예외가 전파되지 않도록 만들 수 있다.

-> Coroutine1 코루틴이 예외를 전파하지 않아 Coroutine2 코루틴이 정상 실행되는 것을 확인할 수 있다.

async 코루틴 빌더를 사용할 때는 전파되는 예외와 await 호출 시 노출되는 예외를 모두 처리해 줘야 함을 명심하자.

```
fun main() = runBlocking<Unit> {
  async(CoroutineName("Coroutine1")) {
    throw Exception("Coroutine1에 예외가 발생했습니다")
  }
  launch(CoroutineName("Coroutine2")) {
    delay(100L)
    println("[${Thread.currentThread().name}] 코루틴 실행")
  }
}
/*
// 결과:
Exception in thread "main" java.lang.Exception: Coroutine1에 예외가 발생했습니다
	at chapter8.code17.Main8_17Kt$main$1$1.invokeSuspend(Main8-17.kt:7)
	at kotlin.coroutines.jvm.internal.BaseContinuationImpl.resumeWith(ContinuationImpl.kt:33)
	...

Process finished with exit code 1
*/
```

```
fun main() = runBlocking<Unit> {
  supervisorScope {
    async(CoroutineName("Coroutine1")) {
      throw Exception("Coroutine1에 예외가 발생했습니다")
    }
    launch(CoroutineName("Coroutine2")) {
      delay(100L)
      println("[${Thread.currentThread().name}] 코루틴 실행")
    }
  }
}
/*
// 결과:
[main @Coroutine2#3] 코루틴 실행
*/
```

### 전파되지 않는 CancellationException
코루틴은 CancellationException 예외가 발생해도 부모 코루틴으로 전파되지 않는다.

Coroutine2 코루틴은 CancellationException을 발생시키고, 부모 코루틴으로 Coroutine1 코루틴을 가지며, Coroutine1 코루틴은 runBlocking 코루틴을 부모로 가진다.

Coroutine2 코루틴에서 발생하는 예외가 일반적인 예외였다면 루트 코루틴까지 예외가 전파돼 모든 코루틴들이 취소됐겠지만, CancellationException은 Coroutine2 코루틴만 취소시키고 전파되지 않는다.

```
fun main() = runBlocking<Unit>(CoroutineName("runBlocking 코루틴")) {
  launch(CoroutineName("Coroutine1")) {
    launch(CoroutineName("Coroutine2")) {
      throw CancellationException()
    }
    delay(100L)
    println("[${Thread.currentThread().name}] 코루틴 실행")
  }
  delay(100L)
  println("[${Thread.currentThread().name}] 코루틴 실행")
}
/*
// 결과:
[main @runBlocking 코루틴#1] 코루틴 실행
[main @Coroutine1#2] 코루틴 실행
*/
```

### 코루틴 취소 시 사용되는 JobCancellationException
왜 JobCancellationException을 부모 코루틴으로 전파하지 않는 것일까?
- CancellationException은 코루틴의 취소에 사용되는 특별한 예외이기 때문이다.

Job 객체에 대해 cancel 함수를 호출하면 CancellationException의 서브 클래스인 JobCancellationException을 발생시켜 코루틴을 취소시킨다.

1초간 지속되는 job을 만들고, invokeOnCompletion 함수를 통해 job에 발생한 예외를 출력하는 콜백을 등록한 후 job.cancel()을 호출해 어떤 예외가 job을 취소시켰는지 확인한다.

```
fun main() = runBlocking<Unit> {
  val job = launch {
    delay(1000L) // 1초간 지속
  }
  job.invokeOnCompletion { exception ->
    println(exception) // 발생한 예외 출력
  }
  job.cancel() // job 취소
}
/*
// 결과:
kotlinx.coroutines.JobCancellationException: StandaloneCoroutine was cancelled; job=StandaloneCoroutine{Cancelled}@7494e528
*/
```

### withTimeOut 사용해 코루틴의 실행 시간 제한하기
withTimeOut 함수는 제한 시간을 두고 작업을 실행할 수 있도록 만든다.

withTimeOut 함수는 작업이 주어진 시간 내에 완료되지 않으면 TimeoutCancellationException을 발생시키는데 TimeoutcancellationException은 CancellationException의 서브 클래스이다.

TimeoutCancellationException이 발생되더라도 예외가 부모 코루틴으로 전파되지 않고 해당 예외가 발생한 코루틴만 취소시킨다.

-> withTimeOut 함수는 실행 시간이 제한돼야 할 필요가 있는 다양한 작업에 사용되며, 대표적으로 네트워크 호출의 실행 시간을 제한하는 데 사용할 수 있다.

```
fun main() = runBlocking<Unit>(CoroutineName("Parent Coroutine")) {
  launch(CoroutineName("Child Coroutine")) {
    withTimeout(1000L) { // 실행 시간을 1초로 제한
      delay(2000L) // 2초의 시간이 걸리는 작업
      println("[${Thread.currentThread().name}] 코루틴 실행")
    }
  }
  delay(2000L)
  println("[${Thread.currentThread().name}] 코루틴 실행")
}
/*
// 결과:
[main @Parent Coroutine#1] 코루틴 실행
*/
```

#### 추가 자료
withTimeOutOrNull 함수를 사용하면 실행 시간을 초과하더라도 코루틴이 취소되지 않고 결과가 반환돼야 할 때 사용하면 된다.

-> 실행 시간을 초과하면 코루틴이 취소되지 않고 내부적으로 예외를 처리하고 null을 반환한다.
```
fun main() = runBlocking<Unit>(CoroutineName("Parent Coroutine")) {
  launch(CoroutineName("Child Coroutine")) {
    val result = withTimeoutOrNull(1000L) { // 실행 시간을 1초로 제한
      delay(2000L) // 2초의 시간이 걸리는 작업
      return@withTimeoutOrNull "결과"
    }
    println(result)
  }
}
/*
// 결과:
null
*/
```

